<?xml version="1.0" ?>
<robot name="tb3_kai" xmlns:xacro="http://ros.org/wiki/xacro">
  <xacro:include filename="$(find tb3kai_spinhokuyo)/urdf/common_properties.xacro"/>
  <xacro:include filename="$(find tb3kai_spinhokuyo)/urdf/turtlebot3_burger.gazebo.xacro"/>

  <!-- World -->
  <link name="world">
  </link>

  <!-- World fixed joint-->
  <joint name="world_fixed" type="fixed">
    <origin xyz="0 0 0" rpy="0 0 0"/>
    <parent link="world"/>
    <child link="base_footprint"/>
  </joint>

  <link name="base_footprint"/>

  <joint name="base_joint" type="fixed">
    <parent link="base_footprint"/>
    <child link="base_link"/>
    <origin xyz="0.0 0.0 0.010" rpy="0 0 0"/>
  </joint>

  <link name="base_link">
    <visual>
      <origin xyz="-0.032 0 0.0" rpy="0 0 0"/>
      <geometry>
        <mesh filename="package://tb3kai_description/meshes/bases/burger_base.stl" scale="0.001 0.001 0.001"/>
      </geometry>
      <material name="orange"/>
    </visual>

    <collision>
      <origin xyz="-0.032 0 0.070" rpy="0 0 0"/>
      <geometry>
        <box size="0.140 0.140 0.140"/>
      </geometry>
    </collision>

    <inertial>
      <origin xyz="-0.032 0 0" rpy="0 0 0"/>
      <mass value="1"/>
      <inertia ixx="0.01" ixy="0.0" ixz="0.0"
               iyy="0.01" iyz="0.0"
               izz="0.01" />
    </inertial>
  </link>


  <!-- AX-18 Motor and stand -->
  <joint name="laser_servo_base_joint" type="fixed">
    <parent link="base_link"/>
    <child link="laser_servo_link"/>
    <origin xyz="0 ${0.051+0.002-0.007} ${0.158+0.038+0.0071}" rpy="0 0 0"/>
    <axis xyz="0 1 0"/>
  </joint>

  <link name="laser_servo_link">
    <visual>
        <origin xyz="0.0003 0 -0.0168" rpy="${M_PI*0.5} 0 -${M_PI*0.5}"/>
      <geometry>
        <mesh filename="package://tb3kai_description/meshes/bases/Ax18.stl" scale="0.001 0.001 0.001"/>
      </geometry>
      <material name="brown"/>
    </visual>

    <collision>
      <origin xyz="0 0 0" rpy="0 0 0"/>
      <geometry>
        <mesh filename="package://tb3kai_description/meshes/bases/Ax18.stl" scale="0.001 0.001 0.001"/>
      </geometry>
    </collision>

    <inertial>
      <origin xyz="0 0 0" />
      <mass value="0.082" />
      <inertia ixx="0.1" ixy="0.0" ixz="0.0"
               iyy="0.1" iyz="0.0"
               izz="0.1" />
    </inertial>


















  </link>
  <!-- End of AX-18 -->

  <!-- Add it for Spin Hokuyo -->
  <joint name="laser_holder_joint" type="revolute"><!-- change type to revolute with limited range -->
    <parent link="base_link"/>
    <child link="laser_holder_link"/>
    <origin xyz="0 0.026 ${0.158+0.038+0.007}" rpy="0 0 0"/>
    <axis xyz="0 1 0"/>
    <limit velocity="8.0" effort="1000" lower="${-M_PI}" upper="${M_PI}" />
  </joint>

  <link name="laser_holder_link">
    <visual>
        <origin xyz="0 0 -0.009" rpy="-${M_PI*0.5} 0 ${M_PI}"/>
      <geometry>
        <mesh filename="package://tb3kai_description/meshes/sensors/laserHolder.stl" scale="0.001 0.001 0.001"/>
      </geometry>
      <material name="red"/>
    </visual>


    <collision>
      <origin xyz="0 0 0" rpy="0 0 0"/>
      <geometry>
        <mesh filename="package://tb3kai_description/meshes/sensors/laserHolder.stl" scale="0.001 0.001 0.001"/>
      </geometry>
    </collision>

    <inertial>
      <origin xyz="0 0 0" />
      <mass value="0.100" />
      <inertia ixx="0.1" ixy="0.0" ixz="0.0"
               iyy="0.1" iyz="0.0"
               izz="0.1" />
    </inertial>




  </link>
  <!-- End of Spin Hokuyo -->

  <!-- Transmission AX-18A ID 3 -->
  <transmission name="tran1">
    <type>transmission_interface/SimpleTransmission</type>
    <joint name="laser_holder_joint">
      <hardwareInterface>hardware_interface/EffortJointInterface</hardwareInterface>
    </joint>
    <actuator name="ax18a3">
      <hardwareInterface>hardware_interface/EffortJointInterface</hardwareInterface>
      <mechanicalReduction>1</mechanicalReduction>
    </actuator>
  </transmission>








  <!-- URG Hokuyo -->
  <joint name="holder_urg_joint" type="fixed">
      <axis xyz="0 0 1" />
      <origin xyz="0 -0.032 ${0.009+0.0054}" rpy="0 0 0"/>
      <parent link="laser_holder_link"/>
      <child link="urg_link"/>
  </joint>

  <link name="urg_link">
      <collision>
          <origin xyz="0 0 0" rpy="0 0 0"/>
          <geometry>
              <box size="0.1 0.1 0.1"/>
          </geometry>
      </collision>
      <visual>
          <origin xyz="0 0 0" rpy="0 0 0"/>
          <geometry>
              <mesh filename="package://tb3kai_description/meshes/sensors/hokuyo.dae"/>
          </geometry>
      </visual>
      <inertial>
          <mass value="1e-5" />
          <origin xyz="0 0 0" rpy="0 0 0"/>
          <inertia ixx="1e-6" ixy="0" ixz="0" iyy="1e-6" iyz="0" izz="1e-6" />
      </inertial>
  </link>
  <!-- End URG Hokuyo -->

</robot>
